Workbook

Sheet Leia-me
A1: Matriz de Análise — RFP nº 2026-017 — Banco Horizonte Fictício S.A. — SOC 24x7 + IAM
A2: Data da análise: 18/10/2026 · Entrega das propostas: 27/11/2026 até 18h (prorrogada pelo Q&A #1) · Perguntas até 05/11/2026
A3: DOCUMENTOS DE ORIGEM FICTÍCIOS PARA TESTE.
A5: Como usar
A6: • 'Matriz': todos os itens analisados, com filtros. Para o JURÍDICO, filtrar 'Impacto Jurídico' = Sim. Para o PRICING, filtrar 'Impacto Pricing' = Sim. As abas 'Jurídico' e 'Pricing' já trazem esses recortes prontos.
A7: • 'Conflitos': divergências entre documentos e a posição adotada.
A8: • 'Esclarecimentos': perguntas prontas para enviar até 05/11/2026 (colunas 'Status' e 'Resposta do banco' para acompanhamento).
A9: • 'Pontuação' e 'Questionário': simulação da nota técnica e recomendação de resposta para QT-01 a QT-06.
A10: • 'Cronograma': marcos oficiais e datas derivadas.
A11: • A coluna 'Status interno' da Matriz está livre para uso das áreas (lista: Aberto / Em análise / Resolvido / Aceito como risco).
A13: Documentos recebidos (na ordem enviada) e hierarquia adotada
A14: Ordem recebida | B14: Arquivo | C14: Documento | D14: Natureza | E14: Data | F14: Observações
A15: 1 | B15: QA_Rodada1_e_Questionario.xlsx | C15: Q&A Rodada 1 + Questionário Técnico | D15: Esclarecimentos oficiais (altera o RFP) + formulário a devolver preenchido | E15: 12/11/2026 | F15: 4 abas: Instruções, Q&A Rodada 1 (6 respostas), Questionário Técnico (QT-01 a QT-06) e 'Pesos' (aba OCULTA, com pesos e regra de penalidade).
A16: 2 | B16: Apresentacao_Ambiente_Atual.pptx | C16: Apresentação do workshop (ambiente atual) | D16: Material informativo do workshop de 22/10/2026 (não é documento normativo) | E16: 22/10/2026 | F16: 5 slides; o slide 5 tem nota do apresentador incluindo subsidiárias no escopo.
A17: 3 | B17: Anexo_I_Especificacao_Tecnica.docx | C17: Anexo I — Especificação Técnica | D17: Anexo normativo do RFP | E17: 15/10/2026 | F17: 6 seções: SOC, SLA, IAM, Transição, Equipe, Responsabilidades do Contratante.
A18: 4 | B18: RFP-2026-017_Servicos_SOC_IAM.pdf | C18: RFP nº 2026-017 v1.0 (documento principal) | D18: Documento principal | E18: 15/10/2026 | F18: 6 páginas. A página 6 (Anexo III — Declaração de Localização de Dados) é imagem escaneada, sem texto pesquisável: transcrita por leitura visual.
A20: Hierarquia adotada (o RFP não define precedência; ver CT-09 / PE-01)
A21: 1. Q&A Rodada 1 (12/11/2026): mais recente; prevalece sobre o que alterar expressamente.
A22: 2. RFP nº 2026-017 (corpo principal) e seus anexos com caráter de formulário (Anexo III).
A23: 3. Anexo I — Especificação Técnica.
A24: 4. Questionário Técnico (inclusive a aba oculta 'Pesos', que revela critério de pontuação).
A25: 5. Apresentação do workshop: apenas informativa; o que estiver só nela é tratado como expectativa/risco de escopo, não como obrigação, até ser formalizado.
A27: Problemas encontrados nos insumos
A28: • Arquivos recebidos fora da ordem lógica (Q&A primeiro, RFP por último). A análise foi reordenada pela hierarquia documental, e o Q&A foi aplicado por cima do RFP e do Anexo I.
A29: • A página 6 do PDF (Anexo III — Declaração de Localização de Dados) é uma imagem escaneada, sem camada de texto. O conteúdo foi transcrito por leitura visual, sem OCR: conferir com o original antes de citar literalmente.
A30: • A planilha do Q&A tem uma aba OCULTA ('Pesos') com pesos do questionário e uma regra de penalidade que não aparece no RFP.
A31: • O Anexo IV (Planilha de Preços), referenciado no RFP 4.3, não foi recebido. O Anexo II não é referenciado nem foi recebido. Não há minuta de contrato.
A32: • Informações relevantes de escopo (subsidiárias com ~900 usuários) estão só nas NOTAS DO APRESENTADOR do slide 5 do PPTX, não no slide visível.
... A38: Baixo: requisito usual / formal

Sheet Resumo
A1: Principais riscos e pontos de atenção (top 10)
A3: # | B3: Ref. matriz | C3: Ponto
A4: 1 | B4: CT-05 | C4: Responsabilidade integral e ilimitada por QUALQUER incidente no ambiente do banco (7.5): candidato a no-go se não for negociada.
A5: 2 | B5: CT-04 | C5: Multa de 10% do valor mensal por ocorrência de SLA, sem teto (o Q&A #4 recusou alterar). Junto com a criticidade definida pelo banco (Anexo I 2.4).
A6: 3 | B6: TS-04 | C6: A volumetria (EPS) só será informada ao vencedor (Q&A #3) e o escopo de 'ativos relevantes' está aberto. O preço fixo carrega risco ilimitado.
A7: 4 | B7: DM-01 | C7: Quatro números de usuários (4.500 / 5.000 / 6.200 / ~7.100 com subsidiárias). O Q&A manda considerar 5.000.
A8: 5 | B8: TS-02 | C8: O Anexo I permite SIEM em nuvem em 'região livre', mas o Anexo III (eliminatório) exige dados e logs só no Brasil.
A9: 6 | B9: CR-04/05 | C9: Transição de 30 dias (RFP) x 60 dias (Anexo I), com o SIEM legado terminando em 31/01/2027 sem prorrogação: go-live sem folga.
A10: 7 | B10: TS-03 | C10: Retenção de logs de 12 meses (1.3) x 5 anos (1.6), sem volumetria. Some-se a migração de 24 meses de histórico (só no workshop).
A11: 8 | B11: AV-05 | C11: Aba OCULTA 'Pesos' no questionário: -2 pts por não obrigatório 'Não atende' (SOAR e threat intel). Critério ausente no RFP.
A12: 9 | B12: AV-02 | C12: Os critérios técnicos somam 65, mas o máximo declarado é 60. A nota de corte de 70% fica indefinida (42 ou 45,5).
A13: 10 | B13: PR-03/04 | C13: O Anexo IV (Planilha de Preços) não foi recebido e o Anexo II não é citado nem foi enviado: pricing final bloqueado.
A16: Contagem da matriz por categoria e risco
A17: Categoria | B17: Alto | C17: Médio | D17: Baixo | E17: Total
A18: Cronograma | B18: =COUNTIFS(Matriz!$B:$B,$A18,Matriz!$J:$J,"Alto") | C18: =COUNTIFS(Matriz!$B:$B,$A18,Matriz!$J:$J,"Médio") | D18: =COUNTIFS(Matriz!$B:$B,$A18,Matriz!$J:$J,"Baixo") | E18: =COUNTIF(Matriz!$B:$B,$A18)
A19: Proposta (forma) | B19: =COUNTIFS(Matriz!$B:$B,$A19,Matriz!$J:$J,"Alto") | C19: =COUNTIFS(Matriz!$B:$B,$A19,Matriz!$J:$J,"Médio") | D19: =COUNTIFS(Matriz!$B:$B,$A19,Matriz!$J:$J,"Baixo") | E19: =COUNTIF(Matriz!$B:$B,$A19)
A20: Habilitação | B20: =COUNTIFS(Matriz!$B:$B,$A20,Matriz!$J:$J,"Alto") | C20: =COUNTIFS(Matriz!$B:$B,$A20,Matriz!$J:$J,"Médio") | D20: =COUNTIFS(Matriz!$B:$B,$A20,Matriz!$J:$J,"Baixo") | E20: =COUNTIF(Matriz!$B:$B,$A20)
A21: Avaliação | B21: =COUNTIFS(Matriz!$B:$B,$A21,Matriz!$J:$J,"Alto") | C21: =COUNTIFS(Matriz!$B:$B,$A21,Matriz!$J:$J,"Médio") | D21: =COUNTIFS(Matriz!$B:$B,$A21,Matriz!$J:$J,"Baixo") | E21: =COUNTIF(Matriz!$B:$B,$A21)
A22: Escopo SOC | B22: =COUNTIFS(Matriz!$B:$B,$A22,Matriz!$J:$J,"Alto") | C22: =COUNTIFS(Matriz!$B:$B,$A22,Matriz!$J:$J,"Médio") | D22: =COUNTIFS(Matriz!$B:$B,$A22,Matriz!$J:$J,"Baixo") | E22: =COUNTIF(Matriz!$B:$B,$A22)
A23: SLA | B23: =COUNTIFS(Matriz!$B:$B,$A23,Matriz!$J:$J,"Alto") | C23: =COUNTIFS(Matriz!$B:$B,$A23,Matriz!$J:$J,"Médio") | D23: =COUNTIFS(Matriz!$B:$B,$A23,Matriz!$J:$J,"Baixo") | E23: =COUNTIF(Matriz!$B:$B,$A23)
A24: Escopo IAM | B24: =COUNTIFS(Matriz!$B:$B,$A24,Matriz!$J:$J,"Alto") | C24: =COUNTIFS(Matriz!$B:$B,$A24,Matriz!$J:$J,"Médio") | D24: =COUNTIFS(Matriz!$B:$B,$A24,Matriz!$J:$J,"Baixo") | E24: =COUNTIF(Matriz!$B:$B,$A24)
A25: Dimensionamento | B25: =COUNTIFS(Matriz!$B:$B,$A25,Matriz!$J:$J,"Alto") | C25: =COUNTIFS(Matriz!$B:$B,$A25,Matriz!$J:$J,"Médio") | D25: =COUNTIFS(Matriz!$B:$B,$A25,Matriz!$J:$J,"Baixo") | E25: =COUNTIF(Matriz!$B:$B,$A25)
A26: Equipe | B26: =COUNTIFS(Matriz!$B:$B,$A26,Matriz!$J:$J,"Alto") | C26: =COUNTIFS(Matriz!$B:$B,$A26,Matriz!$J:$J,"Médio") | D26: =COUNTIFS(Matriz!$B:$B,$A26,Matriz!$J:$J,"Baixo") | E26: =COUNTIF(Matriz!$B:$B,$A26)
A27: Contratual | B27: =COUNTIFS(Matriz!$B:$B,$A27,Matriz!$J:$J,"Alto") | C27: =COUNTIFS(Matriz!$B:$B,$A27,Matriz!$J:$J,"Médio") | D27: =COUNTIFS(Matriz!$B:$B,$A27,Matriz!$J:$J,"Baixo") | E27: =COUNTIF(Matriz!$B:$B,$A27)
A28: Regulatório | B28: =COUNTIFS(Matriz!$B:$B,$A28,Matriz!$J:$J,"Alto") | C28: =COUNTIFS(Matriz!$B:$B,$A28,Matriz!$J:$J,"Médio") | D28: =COUNTIFS(Matriz!$B:$B,$A28,Matriz!$J:$J,"Baixo") | E28: =COUNTIF(Matriz!$B:$B,$A28)
A29: TOTAL | B29: =SUM(B18:B28) | C29: =SUM(C18:C28) | D29: =SUM(D18:D28) | E29: =SUM(E18:E28)
A31: Itens com impacto em Pricing: | C31: =COUNTIF(Matriz!$K:$K,"Sim")
A32: Itens com impacto Jurídico: | C32: =COUNTIF(Matriz!$L:$L,"Sim")

Sheet Matriz
A1: ID | B1: Categoria | C1: Tema | D1: Fonte principal | E1: Outras fontes | F1: Requisito / conteúdo (resumo) | G1: Tipo | H1: Posição vigente (após Q&A) | I1: Conflito / ambiguidade | J1: Risco | K1: Impacto Pricing | L1: Impacto Jurídico | M1: Área responsável | N1: Análise | O1: Ação recomendada | P1: Pergunta (ref.) | Q1: Status interno | R1: Responsável | S1: Comentários das áreas
A2: CR-01 | B2: Cronograma | C2: Entrega das propostas | D2: Q&A #1 | E2: RFP 3.1 | F2: RFP: 20/11/2026 até 18h. Q&A #1 prorroga para 27/11/2026 até 18h. | G2: Prazo | H2: 27/11/2026 até 18h (prorrogado) | I2: Alterado pelo Q&A | J2: Médio | K2: Não | L2: Não | M2: Bid / Comercial | N2: A prorrogação consta só no Q&A. O RFP v1.0 não foi reemitido. | O2: Planejar a entrega para 27/11, 18h, mas confirmar no portal de fornecedores se a data foi atualizada. Até lá, manter o plano B de 20/11. | P2: PE-14 | Q2: Aberto
A3: CR-02 | B3: Cronograma | C3: Workshop do ambiente | D3: RFP 3.1 | E3: PPTX slide 1 | F3: Workshop de apresentação do ambiente em 22/10/2026. | G3: Prazo | H3: 22/10/2026 | I3: — | J3: Baixo | K3: Não | L3: Não | M3: Pré-vendas | N3: A apresentação do workshop traz informações que não estão no RFP (usuários, subsidiárias, migração de logs, meta de falsos positivos). | O3: Participar e levar as perguntas da aba 'Esclarecimentos'. Pedir que o conteúdo do workshop seja formalizado em ata ou Q&A. | P3: PE-02 | Q3: Aberto
A4: CR-03 | B4: Cronograma | C4: Prazo para perguntas | D4: RFP 3.1 | F4: Perguntas até 05/11/2026; respostas divulgadas em 12/11/2026. | G4: Prazo | H4: 05/11/2026 | I4: — | J4: Alto | K4: Não | L4: Não | M4: Bid / Comercial | N4: Este é o último canal formal para resolver os conflitos desta matriz. O Q&A recebido é a 'Rodada 1', o que sugere que pode haver novas rodadas. | O4: Enviar o pacote de perguntas desta matriz antes de 05/11/2026. | P4: — | Q4: Aberto
A5: CR-04 | B5: Cronograma | C5: Início dos serviços x fim do SIEM legado | D5: RFP 3.1 | E5: PPTX slide 3 | F5: Início previsto em 01/02/2027. O contrato do SIEM legado termina em 31/01/2027, sem possibilidade de prorrogação. | G5: Prazo | H5: 01/02/2027 (go-live sem folga) | I5: Sem margem de contingência | J5: Alto | K5: Sim | L5: Sim | M5: Pré-vendas / Jurídico | N5: Não há folga: se o novo SIEM não estiver operando em 01/02/2027, o banco fica sem monitoramento. A migração de 24 meses de logs (TS-06) também precisa acontecer antes de 31/01/2027, enquanto o legado ainda existe. A data de assinatura do contrato não foi informada. | O5: Pedir a data prevista de assinatura. Condicionar os prazos de transição à assinatura e ao cumprimento das obrigações do Contratante. Prever plano de contingência. | P5: PE-03 | Q5: Aberto
A6: CR-05 | B6: Cronograma | C6: Prazo de transição | D6: RFP 3.2 | E6: Anexo I 4.1 | F6: RFP 3.2: transição concluída em até 30 dias corridos da assinatura. Anexo I 4.1: até 60 dias corridos da assinatura. | G6: Obrigatório | H6: INDEFINIDO: 30 x 60 dias (adotar 30 dias como pior caso) | I6: CONFLITO RFP x Anexo I | J6: Alto | K6: Sim | L6: Sim | M6: Pré-vendas / Pricing / Jurídico | N6: Os dois documentos divergem e o Q&A não tratou do tema. O plano de transição vale 10 pontos (6.2). Com 30 dias, a equipe de onboarding fica mais concentrada e mais cara. Somado à multa de 10% por SLA (CT-04), o atraso na transição é um risco relevante. | O6: Pedir esclarecimento. Precificar e planejar para 30 dias, com a premissa de que a contagem só corre após a entrega da documentação (CR-07) e dos acessos (VPN). | P6: PE-04 | Q6: Aberto
A7: CR-06 | B7: Cronograma | C7: Operação paralela sem custo | D7: Anexo I 4.2 | E7: PPTX slide 3 | F7: Durante a transição, operar em paralelo com o fornecedor atual, sem custo adicional para o Contratante. | G7: Obrigatório | H7: Paralelo sem custo adicional | I7: Ambiguidade (duração do paralelo) | J7: Médio | K7: Sim | L7: Sim | M7: Pricing | N7: O custo da operação paralela tem de ser diluído na mensalidade. A duração depende de CR-05 e fica limitada pelo fim do SIEM legado em 31/01/2027. | O7: Embutir o custo de transição e paralelo no preço, ou em uma linha de setup se o Anexo IV permitir. Limitar o paralelo ao prazo de transição. | P7: PE-04 | Q7: Aberto
A8: CR-07 | B8: Cronograma | C8: Documentação do ambiente pelo Contratante | D8: Anexo I 6.2 | E8: Anexo I 6.1 | F8: Contratante entrega a documentação técnica em até 10 dias após a assinatura e disponibiliza VPN (6.1). | G8: Obrigação do Contratante | H8: 10 dias após a assinatura | I8: Ambiguidade (impacto no prazo de 30 dias) | J8: Médio | K8: Não | L8: Sim | M8: Jurídico / Pré-vendas | N8: Com transição de 30 dias, o banco pode consumir até 1/3 do prazo antes de entregar a documentação. Não há previsão de que atrasos do Contratante suspendam os prazos da Contratada. | O8: Incluir premissa: prazos de transição e SLAs ficam suspensos enquanto houver pendências do Contratante (documentação, VPN, acessos). | P8: PE-04 | Q8: Aberto
A9: PR-01 | B9: Proposta (forma) | C9: Idioma e canal | D9: RFP 4.1 | F9: Proposta em língua portuguesa, enviada exclusivamente pelo portal de fornecedores. | G9: Obrigatório (forma) | H9: Português; somente pelo portal | I9: — | J9: Baixo | K9: Não | L9: Não | M9: Bid / Comercial | N9: Requisito formal. | O9: Confirmar o cadastro e o acesso ao portal com antecedência e fazer um teste de upload. | P9: — | Q9: Aberto
A10: PR-02 | B10: Proposta (forma) | C10: Limite de páginas | D10: RFP 4.2 | F10: Proposta técnica com no máximo 40 páginas, excluídos os anexos. | G10: Obrigatório (forma) | H10: 40 páginas | I10: — | J10: Médio | K10: Não | L10: Não | M10: Bid / Comercial | N10: O RFP não diz qual é a consequência de exceder o limite. Os critérios técnicos (65 pontos) têm de caber em 40 páginas. | O10: Estruturar a proposta pelos 4 critérios do item 6.2. Levar detalhes para anexos. | P10: — | Q10: Aberto
A11: PR-03 | B11: Proposta (forma) | C11: Planilha de preços (Anexo IV) | D11: RFP 4.3 | F11: Proposta comercial conforme a planilha modelo do Anexo IV — Planilha de Preços. | G11: Obrigatório (forma) | H11: Anexo IV NÃO RECEBIDO | I11: DOCUMENTO AUSENTE | J11: Alto | K11: Sim | L11: Não | M11: Pricing / Bid | N11: O Anexo IV não está entre os arquivos recebidos. Sem ele não se sabe a estrutura de preço (por usuário, por EPS, fixo mensal, setup), o que impede o pricing final. | O11: Baixar o Anexo IV no portal. Se não existir, pedir via Q&A. | P11: PE-05 | Q11: Aberto
A12: PR-04 | B12: Proposta (forma) | C12: Anexo II | D12: RFP (numeração) | F12: O RFP menciona Anexos I, III e IV. O Anexo II não é citado nem foi recebido. | G12: Verificação | H12: Anexo II desconhecido | I12: DOCUMENTO AUSENTE / lacuna | J12: Médio | K12: Não | L12: Sim | M12: Bid / Jurídico | N12: Pode ser a minuta de contrato ou um modelo de atestado. Se for a minuta, é essencial para o jurídico. | O12: Confirmar no portal se existe Anexo II (minuta contratual?) e pedir o envio. | P12: PE-05 | Q12: Aberto
A13: PR-05 | B13: Proposta (forma) | C13: Questionário técnico integral | D13: RFP 4.4 | E13: XLSX aba Instruções | F13: O questionário deve ser integralmente preenchido. Instruções da planilha: 'o preenchimento de todas as abas é obrigatório; questionários incompletos serão desclassificados'. | G13: Eliminatório | H13: Preencher as colunas D e E de QT-01 a QT-06 | I13: Ambiguidade ('todas as abas') | J13: Alto | K13: Não | L13: Sim | M13: Pré-vendas / Bid | N13: As abas 'Q&A Rodada 1' e 'Pesos' (oculta) não são de preenchimento, mas a instrução diz 'todas as abas'. O risco de desclassificação é formal. | O13: Preencher todo o Questionário Técnico, inclusive Comentários. Não alterar as demais abas. Confirmar via Q&A quais abas exigem preenchimento. | P13: PE-13 | Q13: Aberto
A14: PR-06 | B14: Proposta (forma) | C14: Declaração de localização de dados (Anexo III) | D14: RFP p.6 (Anexo III, escaneado) | E14: RFP 5.1c; Q&A #2 | F14: Declaração assinada pelo representante legal: todos os dados do Banco, inclusive logs de segurança, serão armazenados e processados exclusivamente em território nacional durante toda a vigência. Deve ser entregue com a proposta, sob pena de inabilitação. | G14: Eliminatório | H14: Obrigatória: dados e logs só no Brasil | I14: CONFLITO com Anexo I 1.2 (nuvem em região livre) | J14: Alto | K14: Sim | L14: Sim | M14: Jurídico / Pré-vendas | N14: A declaração vincula toda a cadeia: SIEM em nuvem, backups, DR, threat intel e suporte do fabricante com acesso a dados. Assinar exige garantir que nenhum componente (inclusive telemetria do fabricante do SIEM) processe dados fora do Brasil. A página é imagem, sem texto extraível. | O14: Validar a arquitetura antes da assinatura: região Brasil do hyperscaler, DR no Brasil e suporte do fabricante sem acesso a dados fora do país. Colher a assinatura do representante legal com procuração válida. | P14: PE-06 | Q14: Aberto
A15: HB-01 | B15: Habilitação | C15: ISO/IEC 27001 | D15: RFP 5.1a | E15: QT-01 (obrigatório, peso 3) | F15: Certificado ISO/IEC 27001 vigente, emitido por organismo acreditado, com escopo que inclua os serviços de SOC. | G15: Eliminatório | H15: Obrigatório | I15: — | J15: Alto | K15: Não | L15: Não | M15: Compliance / Bid | N15: Checar a validade do certificado até a data de entrega e, de preferência, durante o contrato. O escopo tem de citar o SOC explicitamente. | O15: Separar o certificado e a declaração de escopo, e confirmar a acreditação do organismo. | P15: — | Q15: Aberto
A16: HB-02 | B16: Habilitação | C16: Atestados de capacidade técnica | D16: RFP 5.1b | F16: No mínimo 3 atestados de serviços de SOC para instituições financeiras, com ambiente de no mínimo 2.000 usuários. | G16: Eliminatório | H16: ≥3 atestados SOC / IF / ≥2.000 usuários | I16: Ambiguidade ('instituição financeira') | J16: Alto | K16: Não | L16: Não | M16: Bid / Comercial | N16: Não está claro se seguradoras, corretoras ou cooperativas contam como 'instituição financeira', nem se os atestados precisam ser de contratos vigentes. | O16: Levantar atestados elegíveis. Se houver dúvida sobre o enquadramento, perguntar via Q&A. | P16: PE-15 | Q16: Aberto
A17: HB-03 | B17: Habilitação | C17: SOC em território nacional | D17: RFP 5.1c | E17: Q&A #2; Anexo III | F17: Comprovar que o SOC está localizado em território nacional. Q&A #2: não é permitido operar o SOC a partir de outro país. | G17: Eliminatório | H17: SOC no Brasil (confirmado no Q&A #2) | I17: Confirmado pelo Q&A | J17: Alto | K17: Sim | L17: Não | M17: Pré-vendas / Bid | N17: Exclui follow-the-sun com centros no exterior. O RFP não define o meio de comprovação. | O17: Preparar a comprovação (endereço, contrato de locação, fotos, certificação do site). | P17: — | Q17: Aberto
A18: HB-04 | B18: Habilitação | C18: Equipe certificada | D18: RFP 5.2 | E18: QT-06 (obrigatório, peso 2); Anexo I 5.1 | F18: O proponente deverá possuir equipe técnica 'devidamente certificada'. | G18: Obrigatório (critério aberto) | H18: Certificações não especificadas | I18: Ambiguidade (critério subjetivo) | J18: Médio | K18: Não | L18: Não | M18: Pré-vendas / RH | N18: O texto não diz quais certificações nem quantos profissionais. Única exigência objetiva: coordenador com CISSP (EQ-01). | O18: Anexar a matriz de certificações da equipe (CISSP, GCIH, CEH, Security+, certificações dos fabricantes de SIEM e IAM). | P18: PE-15 | Q18: Aberto
A19: AV-01 | B19: Avaliação | C19: Composição da nota final | D19: RFP 6.1 | F19: Nota final = Nota Técnica (peso 60%) + Nota de Preço (peso 40%). | G19: Critério | H19: 60/40 | I19: Ambiguidade (fórmula de preço) | J19: Médio | K19: Sim | L19: Não | M19: Pricing | N19: A fórmula da Nota de Preço não foi informada (proporcional ao menor preço? faixas?). Sem ela não dá para simular o trade-off entre preço e técnica. | O19: Pedir a fórmula da Nota de Preço. | P19: PE-07 | Q19: Aberto
A20: AV-02 | B20: Avaliação | C20: Soma dos critérios técnicos | D20: RFP 6.2 | F20: Nota Técnica de no máximo 60 pontos, mas os critérios somam 65 (Metodologia 20 + Equipe 20 + Ferramentas 15 + Transição 10). | G20: Critério | H20: INDEFINIDO: 60 x 65 | I20: INCONSISTÊNCIA interna do RFP | J20: Alto | K20: Não | L20: Sim | M20: Bid / Jurídico | N20: Erro aritmético no RFP. Afeta a nota de corte (AV-03) e a normalização da nota técnica. | O20: Pedir correção via Q&A. Enquanto isso, mirar no corte mais exigente (45,5 pontos). | P20: PE-07 | Q20: Aberto
A21: AV-03 | B21: Avaliação | C21: Nota técnica mínima | D21: RFP 6.3 | E21: RFP 6.2 | F21: Desclassificação se a Nota Técnica for menor que 70% da pontuação máxima. | G21: Eliminatório | H21: Corte de 42,0 pts (base 60) ou 45,5 pts (base 65) | I21: Depende de AV-02 | J21: Alto | K21: Não | L21: Não | M21: Pré-vendas | N21: A penalidade oculta do questionário (AV-05) pode tirar até 4 pontos. Isso pesa numa margem estreita. | O21: Mirar em pelo menos 50 pontos. Ver a aba 'Pontuação'. | P21: PE-07 | Q21: Aberto
A22: AV-04 | B22: Avaliação | C22: Desempate | D22: RFP 6.4 | F22: Em caso de empate, prevalece a proposta de menor preço. | G22: Critério | H22: Menor preço | I22: — | J22: Baixo | K22: Sim | L22: Não | M22: Pricing | N22: Reforça o peso do preço. | O22: — | P22: — | Q22: Aberto
A23: AV-05 | B23: Avaliação | C23: Pesos e penalidade ocultos no questionário | D23: XLSX aba 'Pesos' (OCULTA) | E23: Questionário QT-01 a QT-06 | F23: Aba oculta com pesos (QT-01=3, QT-02=1, QT-03=2, QT-04=3, QT-05=2, QT-06=2) e a regra: 'requisitos não obrigatórios respondidos como Não atende reduzem a Nota Técnica em 2 pontos cada'. | G23: Critério (não divulgado no RFP) | H23: QT-02 (SOAR) e QT-05 (Threat Intel) = -2 pts cada se 'Não atende' | I23: CRITÉRIO OCULTO / não previsto no RFP | J23: Alto | K23: Sim | L23: Sim | M23: Pré-vendas / Pricing / Jurídico | N23: O critério não aparece nos itens 6.1 a 6.3. Requisitos 'não obrigatórios' acabam pontuando: deixar de oferecer SOAR ou threat intel custa até 4 pontos. A regra não diz o que acontece com 'Parcial'. Os pesos não têm uso explicado. | O23: Oferecer SOAR e threat intelligence (ao menos como 'Atende' com escopo básico, ou 'Parcial' bem justificado). Jurídico: avaliar se cabe questionar a transparência do critério. Pedir confirmação via Q&A. | P23: PE-08 | Q23: Aberto
A24: AV-06 | B24: Avaliação | C24: Detalhamento dos critérios técnicos | D24: RFP 6.2 | F24: Critérios sem rubrica: não se sabe como cada critério é pontuado. | G24: Critério | H24: Sem rubrica | I24: Ambiguidade | J24: Médio | K24: Não | L24: Não | M24: Pré-vendas | N24: A atribuição de nota fica subjetiva. | O24: Pedir a rubrica ou os subcritérios. | P24: PE-07 | Q24: Aberto
A25: TS-01 | B25: Escopo SOC | C25: Monitoramento 24x7x365 | D25: Anexo I 1.1 | E25: RFP 2.1 | F25: Monitoramento contínuo de eventos de segurança em regime 24x7x365. | G25: Obrigatório | H25: 24x7x365 | I25: — | J25: Médio | K25: Sim | L25: Não | M25: Pré-vendas / Pricing | N25: É a base de dimensionamento dos turnos (mínimo de 5 a 6 FTEs por posição 24x7). | O25: Dimensionar a escala com base em cerca de 1.200 alertas/dia (TS-07). | P25: — | Q25: Aberto
A26: TS-02 | B26: Escopo SOC | C26: SIEM fornecido pelo proponente / localização | D26: Anexo I 1.2 | E26: Anexo III; RFP 1.2 (Res. CMN 4.893); QT-04 | F26: O proponente fornece o SIEM, 'podendo ser disponibilizado em nuvem pública, em região de livre escolha do proponente'. | G26: Obrigatório | H26: SIEM do proponente, OBRIGATORIAMENTE em região no Brasil | I26: CONFLITO Anexo I 1.2 x Anexo III | J26: Alto | K26: Sim | L26: Sim | M26: Pré-vendas / Pricing / Jurídico | N26: A 'região de livre escolha' contradiz a declaração do Anexo III (dados e logs só no Brasil, sob pena de inabilitação). Prevalece a regra mais restritiva e eliminatória. Regiões no Brasil costumam custar mais, e alguns SIEM SaaS não têm instância no país. | O26: Arquitetar e precificar o SIEM 100% no Brasil (inclusive DR e backup). Responder QT-04 de forma coerente. Pedir confirmação via Q&A. | P26: PE-06 | Q26: Aberto
A27: TS-03 | B27: Escopo SOC | C27: Retenção de logs | D27: Anexo I 1.3 | E27: Anexo I 1.6; QT-03 | F27: 1.3: logs retidos por no mínimo 12 meses. 1.6: para auditoria, logs mantidos por 5 anos. QT-03: 'retém os logs online por no mínimo 12 meses?'. | G27: Obrigatório | H27: Premissa: 12 meses online + 5 anos em arquivo (cold storage) | I27: CONFLITO interno do Anexo I (12 meses x 5 anos) | J27: Alto | K27: Sim | L27: Sim | M27: Pricing / Pré-vendas / Jurídico | N27: A leitura mais coerente com o QT-03 é 12 meses de retenção online (pesquisável) e 5 anos de arquivo. Não está definido: tempo de recuperação do arquivo, quem guarda os logs após o fim do contrato, se há devolução ao final e se os 5 anos correm durante ou após a vigência. O volume é desconhecido (EPS não informado: TS-04). | O27: Precificar armazenamento em camadas (hot 12 meses, cold 5 anos) com preço unitário por GB/TB excedente. Definir a devolução dos logs ao fim do contrato. | P27: PE-09 | Q27: Aberto
A28: TS-04 | B28: Escopo SOC | C28: Integração do SIEM com 'todos os ativos relevantes' / volumetria | D28: Anexo I 1.4 | E28: Q&A #3; PPTX slide 2 | F28: SIEM integrado a todos os ativos relevantes. Q&A #3: a volumetria (EPS) será informada somente ao vencedor. PPTX: 850 servidores (70% Windows, 30% Linux), 2 data centers (SP e Campinas) e 2 nuvens públicas. | G28: Obrigatório | H28: Escopo aberto; EPS desconhecido | I28: Ambiguidade crítica (escopo e volumetria) | J28: Alto | K28: Sim | L28: Sim | M28: Pricing / Pré-vendas / Jurídico | N28: Licenças de SIEM e armazenamento costumam ser cobrados por EPS ou GB/dia. Sem a volumetria, o preço fixo carrega um risco ilimitado de sobrecusto. 'Ativos relevantes' não está definido: não se sabe se inclui estações, rede, aplicações, SaaS ou subsidiárias. | O28: Declarar uma premissa de EPS e GB/dia estimados (ex.: com base em 850 servidores, 2 DCs e 2 nuvens), com faixa contratada e preço unitário por excedente. Definir a lista de fontes de log no anexo da proposta. Insistir na volumetria via Q&A. | P28: PE-10 | Q28: Aberto
A29: TS-05 | B29: Escopo SOC | C29: Resposta a incidentes | D29: Anexo I 1.5 | E29: Anexo I 6.1 | F29: Resposta a incidentes, incluindo contenção, erradicação e relatório pós-incidente. | G29: Obrigatório | H29: IR incluso | I29: Ambiguidade (limites do IR) | J29: Alto | K29: Sim | L29: Sim | M29: Pré-vendas / Pricing / Jurídico | N29: Não há limites: não se sabe se o atendimento é remoto ou presencial, se inclui forense e recuperação, nem quantas horas ou incidentes estão cobertos. Somado à responsabilidade ilimitada (CT-05), executar contenção e erradicação aumenta a exposição. | O29: Definir o escopo de IR (remoto, banco de horas, forense como opcional) e as responsabilidades de cada parte em matriz RACI. | P29: PE-11 | Q29: Aberto
A30: TS-06 | B30: Escopo SOC | C30: Migração de 24 meses de logs históricos | D30: PPTX slide 5 | E30: Anexo I 1.3/1.6; PPTX slide 3 | F30: Expectativa apresentada no workshop: migrar 24 meses de logs históricos do SIEM legado para a nova plataforma. | G30: Expectativa (não formalizada) | H30: Fora do RFP/Anexo I: tratar como opcional | I30: ESCOPO NÃO FORMALIZADO | J30: Alto | K30: Sim | L30: Sim | M30: Pricing / Pré-vendas | N30: Não consta no RFP nem no Anexo I. O volume é desconhecido e a migração depende do fornecedor e do formato do SIEM legado, cujo contrato acaba em 31/01/2027. Se virar obrigação depois, gera custo não precificado. | O30: Perguntar via Q&A se faz parte do escopo. Cotar como item opcional e separado, com premissas de volume e formato e com a cooperação do fornecedor atual. | P30: PE-02 | Q30: Aberto
A31: TS-07 | B31: Escopo SOC | C31: Meta de falsos positivos | D31: PPTX slide 4 | E31: Anexo I 2 | F31: Hoje são cerca de 1.200 alertas/dia e 70% de falsos positivos. Meta: 10% de falsos positivos no primeiro trimestre de operação. | G31: Expectativa (não formalizada) | H31: Não é SLA contratual (não consta no Anexo I 2) | I31: Expectativa x SLA | J31: Médio | K31: Sim | L31: Sim | M31: Pré-vendas / Jurídico | N31: Sair de 70% para 10% em 3 meses é agressivo, depende do tuning e da cooperação do banco e pode virar critério de aceite informal. Se for incluída como SLA, incide multa de 10% (CT-04). | O31: Apresentar a redução de falsos positivos como plano de tuning progressivo, sem compromisso contratual de 10% no primeiro trimestre. Pedir confirmação de que não é SLA. | P31: PE-02 | Q31: Aberto
A32: TS-08 | B32: Escopo SOC | C32: Visão unificada de riscos para a diretoria | D32: PPTX slide 5 | F32: Expectativa: visão unificada de riscos para a diretoria. | G32: Expectativa (não formalizada) | H32: Escopo não especificado | I32: Ambiguidade | J32: Baixo | K32: Sim | L32: Não | M32: Pré-vendas | N32: Pode significar dashboard executivo ou GRC. Não está especificado. | O32: Oferecer dashboard executivo dentro do relatório mensal (SL-03) e deixar GRC como opcional. | P32: PE-02 | Q32: Aberto
A33: TS-09 | B33: Escopo SOC | C33: SOAR | D33: QT-02 (não obrigatório, peso 1) | E33: Aba Pesos | F33: Integração nativa com plataforma SOAR. | G33: Desejável (pontuável/penalizável) | H33: Oferecer: 'Não atende' = -2 pts | I33: Ver AV-05 | J33: Médio | K33: Sim | L33: Não | M33: Pré-vendas / Pricing | N33: Não consta no Anexo I, mas é penalizado se não for atendido. Também ajuda a cumprir o SLA de 15 minutos e a meta de falsos positivos. | O33: Incluir SOAR (nativo do SIEM ou ferramenta própria) no preço base. | P33: PE-08 | Q33: Aberto
A34: TS-10 | B34: Escopo SOC | C34: Threat intelligence | D34: QT-05 (não obrigatório, peso 2) | E34: Aba Pesos | F34: Serviço de threat intelligence. | G34: Desejável (pontuável/penalizável) | H34: Oferecer: 'Não atende' = -2 pts | I34: Ver AV-05 | J34: Médio | K34: Sim | L34: Sim | M34: Pré-vendas / Pricing | N34: Não consta no Anexo I. Feeds de threat intel podem processar dados fora do Brasil, o que conflita com o Anexo III. | O34: Incluir threat intel (feeds e boletins) com garantia de que os dados do banco não saem do país. | P34: PE-08 | Q34: Aberto
A35: SL-01 | B35: SLA | C35: Início de tratamento de incidentes críticos | D35: Anexo I 2.1 | E35: RFP 7.4 | F35: Tempo máximo de 15 minutos para iniciar o tratamento de incidentes críticos. | G35: Obrigatório (SLA) | H35: 15 min | I35: — | J35: Alto | K35: Sim | L35: Sim | M35: Pré-vendas / Jurídico | N35: Cada violação gera multa de 10% do valor mensal (CT-04). Não está definido o marco inicial: detecção, alerta ou abertura do chamado. | O35: Definir o marco de início e de 'início do tratamento'. Dimensionar o N2 de plantão. | P35: PE-12 | Q35: Aberto
A36: SL-02 | B36: SLA | C36: Disponibilidade do SIEM | D36: Anexo I 2.2 | E36: RFP 7.4 | F36: Disponibilidade mínima mensal de 99,9% da plataforma SIEM. | G36: Obrigatório (SLA) | H36: 99,9% mensal (~43 min/mês) | I36: — | J36: Médio | K36: Sim | L36: Sim | M36: Pré-vendas / Jurídico | N36: Depende do SLA do provedor de nuvem e do fabricante. Não define janelas de manutenção nem exclusões. | O36: Prever exclusões (manutenção programada, força maior, falhas do Contratante) e alinhar com o SLA do hyperscaler. | P36: PE-12 | Q36: Aberto
A37: SL-03 | B37: SLA | C37: Relatório mensal | D37: Anexo I 2.3 | E37: RFP 7.4 | F37: Relatório mensal de indicadores até o 5º dia útil do mês seguinte. | G37: Obrigatório (SLA) | H37: 5º dia útil | I37: — | J37: Baixo | K37: Não | L37: Sim | M37: Pré-vendas | N37: Um atraso, mesmo pequeno, gera multa de 10% (CT-04), uma penalidade desproporcional. | O37: Automatizar o relatório. Pedir multas graduadas por tipo de SLA. | P37: PE-12 | Q37: Aberto
A38: SL-04 | B38: SLA | C38: Classificação de criticidade | D38: Anexo I 2.4 | F38: A criticidade dos incidentes segue a matriz de classificação do Contratante. | G38: Obrigatório | H38: Matriz não fornecida | I38: Ambiguidade (matriz desconhecida) | J38: Alto | K38: Sim | L38: Sim | M38: Pré-vendas / Jurídico | N38: O Contratante define sozinho o que é 'crítico' e, com isso, o volume de SLA de 15 minutos e de multas. | O38: Pedir a matriz. Propor que a classificação seja acordada na transição e que mudanças passem por governança. | P38: PE-12 | Q38: Aberto
A39: IA-01 | B39: Escopo IAM | C39: Ciclo de vida de identidades / revogação em 24h | D39: Anexo I 3.1 | E39: PPTX slide 3 | F39: Gestão de admissão, movimentação e desligamento, com revogação dos acessos de desligados em até 24 horas. Ambiente atual: Active Directory + scripts internos. | G39: Obrigatório | H39: Revogação em 24h | I39: Ambiguidade (gatilho e ferramenta) | J39: Alto | K39: Sim | L39: Sim | M39: Pré-vendas / Pricing | N39: O prazo depende de o RH comunicar o desligamento. Não se sabe se o proponente fornece ferramenta de IGA nem quais sistemas-alvo entram, além do AD. | O39: Definir o gatilho (evento do RH), os sistemas-alvo e se haverá ferramenta de IGA fornecida. Cotar a integração com o RH. | P39: PE-11 | Q39: Aberto
A40: IA-02 | B40: Escopo IAM | C40: MFA para privilegiados | D40: Anexo I 3.2 | F40: MFA obrigatório para 100% dos usuários com acesso privilegiado. | G40: Obrigatório | H40: 100% privilegiados | I40: — | J40: Médio | K40: Sim | L40: Não | M40: Pré-vendas / Pricing | N40: O número de contas privilegiadas não foi informado, e não se sabe se a solução de MFA é fornecida pelo proponente. | O40: Definir premissa de quantidade de contas privilegiadas e da solução de MFA. | P40: PE-11 | Q40: Aberto
...

Sheet Jurídico
A1: ID | B1: Categoria | C1: Tema | D1: Fonte principal | E1: Outras fontes | F1: Requisito / conteúdo (resumo) | G1: Posição vigente (após Q&A) | H1: Conflito / ambiguidade | I1: Risco | J1: Análise | K1: Ação recomendada | L1: Pergunta (ref.)
A2: CR-04 | B2: Cronograma | C2: Início dos serviços x fim do SIEM legado | D2: RFP 3.1 | E2: PPTX slide 3 | F2: Início previsto em 01/02/2027. O contrato do SIEM legado termina em 31/01/2027, sem possibilidade de prorrogação. | G2: 01/02/2027 (go-live sem folga) | H2: Sem margem de contingência | I2: Alto | J2: Não há folga: se o novo SIEM não estiver operando em 01/02/2027, o banco fica sem monitoramento. A migração de 24 meses de logs (TS-06) também precisa acontecer antes de 31/01/2027, enquanto o legado ainda existe. A data de assinatura do contrato não foi informada. | K2: Pedir a data prevista de assinatura. Condicionar os prazos de transição à assinatura e ao cumprimento das obrigações do Contratante. Prever plano de contingência. | L2: PE-03
A3: CR-05 | B3: Cronograma | C3: Prazo de transição | D3: RFP 3.2 | E3: Anexo I 4.1 | F3: RFP 3.2: transição concluída em até 30 dias corridos da assinatura. Anexo I 4.1: até 60 dias corridos da assinatura. | G3: INDEFINIDO: 30 x 60 dias (adotar 30 dias como pior caso) | H3: CONFLITO RFP x Anexo I | I3: Alto | J3: Os dois documentos divergem e o Q&A não tratou do tema. O plano de transição vale 10 pontos (6.2). Com 30 dias, a equipe de onboarding fica mais concentrada e mais cara. Somado à multa de 10% por SLA (CT-04), o atraso na transição é um risco relevante. | K3: Pedir esclarecimento. Precificar e planejar para 30 dias, com a premissa de que a contagem só corre após a entrega da documentação (CR-07) e dos acessos (VPN). | L3: PE-04
A4: PR-05 | B4: Proposta (forma) | C4: Questionário técnico integral | D4: RFP 4.4 | E4: XLSX aba Instruções | F4: O questionário deve ser integralmente preenchido. Instruções da planilha: 'o preenchimento de todas as abas é obrigatório; questionários incompletos serão desclassificados'. | G4: Preencher as colunas D e E de QT-01 a QT-06 | H4: Ambiguidade ('todas as abas') | I4: Alto | J4: As abas 'Q&A Rodada 1' e 'Pesos' (oculta) não são de preenchimento, mas a instrução diz 'todas as abas'. O risco de desclassificação é formal. | K4: Preencher todo o Questionário Técnico, inclusive Comentários. Não alterar as demais abas. Confirmar via Q&A quais abas exigem preenchimento. | L4: PE-13
A5: PR-06 | B5: Proposta (forma) | C5: Declaração de localização de dados (Anexo III) | D5: RFP p.6 (Anexo III, escaneado) | E5: RFP 5.1c; Q&A #2 | F5: Declaração assinada pelo representante legal: todos os dados do Banco, inclusive logs de segurança, serão armazenados e processados exclusivamente em território nacional durante toda a vigência. Deve ser entregue com a proposta, sob pena de inabilitação. | G5: Obrigatória: dados e logs só no Brasil | H5: CONFLITO com Anexo I 1.2 (nuvem em região livre) | I5: Alto | J5: A declaração vincula toda a cadeia: SIEM em nuvem, backups, DR, threat intel e suporte do fabricante com acesso a dados. Assinar exige garantir que nenhum componente (inclusive telemetria do fabricante do SIEM) processe dados fora do Brasil. A página é imagem, sem texto extraível. | K5: Validar a arquitetura antes da assinatura: região Brasil do hyperscaler, DR no Brasil e suporte do fabricante sem acesso a dados fora do país. Colher a assinatura do representante legal com procuração válida. | L5: PE-06
A6: AV-02 | B6: Avaliação | C6: Soma dos critérios técnicos | D6: RFP 6.2 | F6: Nota Técnica de no máximo 60 pontos, mas os critérios somam 65 (Metodologia 20 + Equipe 20 + Ferramentas 15 + Transição 10). | G6: INDEFINIDO: 60 x 65 | H6: INCONSISTÊNCIA interna do RFP | I6: Alto | J6: Erro aritmético no RFP. Afeta a nota de corte (AV-03) e a normalização da nota técnica. | K6: Pedir correção via Q&A. Enquanto isso, mirar no corte mais exigente (45,5 pontos). | L6: PE-07
A7: AV-05 | B7: Avaliação | C7: Pesos e penalidade ocultos no questionário | D7: XLSX aba 'Pesos' (OCULTA) | E7: Questionário QT-01 a QT-06 | F7: Aba oculta com pesos (QT-01=3, QT-02=1, QT-03=2, QT-04=3, QT-05=2, QT-06=2) e a regra: 'requisitos não obrigatórios respondidos como Não atende reduzem a Nota Técnica em 2 pontos cada'. | G7: QT-02 (SOAR) e QT-05 (Threat Intel) = -2 pts cada se 'Não atende' | H7: CRITÉRIO OCULTO / não previsto no RFP | I7: Alto | J7: O critério não aparece nos itens 6.1 a 6.3. Requisitos 'não obrigatórios' acabam pontuando: deixar de oferecer SOAR ou threat intel custa até 4 pontos. A regra não diz o que acontece com 'Parcial'. Os pesos não têm uso explicado. | K7: Oferecer SOAR e threat intelligence (ao menos como 'Atende' com escopo básico, ou 'Parcial' bem justificado). Jurídico: avaliar se cabe questionar a transparência do critério. Pedir confirmação via Q&A. | L7: PE-08
A8: TS-02 | B8: Escopo SOC | C8: SIEM fornecido pelo proponente / localização | D8: Anexo I 1.2 | E8: Anexo III; RFP 1.2 (Res. CMN 4.893); QT-04 | F8: O proponente fornece o SIEM, 'podendo ser disponibilizado em nuvem pública, em região de livre escolha do proponente'. | G8: SIEM do proponente, OBRIGATORIAMENTE em região no Brasil | H8: CONFLITO Anexo I 1.2 x Anexo III | I8: Alto | J8: A 'região de livre escolha' contradiz a declaração do Anexo III (dados e logs só no Brasil, sob pena de inabilitação). Prevalece a regra mais restritiva e eliminatória. Regiões no Brasil costumam custar mais, e alguns SIEM SaaS não têm instância no país. | K8: Arquitetar e precificar o SIEM 100% no Brasil (inclusive DR e backup). Responder QT-04 de forma coerente. Pedir confirmação via Q&A. | L8: PE-06
A9: TS-03 | B9: Escopo SOC | C9: Retenção de logs | D9: Anexo I 1.3 | E9: Anexo I 1.6; QT-03 | F9: 1.3: logs retidos por no mínimo 12 meses. 1.6: para auditoria, logs mantidos por 5 anos. QT-03: 'retém os logs online por no mínimo 12 meses?'. | G9: Premissa: 12 meses online + 5 anos em arquivo (cold storage) | H9: CONFLITO interno do Anexo I (12 meses x 5 anos) | I9: Alto | J9: A leitura mais coerente com o QT-03 é 12 meses de retenção online (pesquisável) e 5 anos de arquivo. Não está definido: tempo de recuperação do arquivo, quem guarda os logs após o fim do contrato, se há devolução ao final e se os 5 anos correm durante ou após a vigência. O volume é desconhecido (EPS não informado: TS-04). | K9: Precificar armazenamento em camadas (hot 12 meses, cold 5 anos) com preço unitário por GB/TB excedente. Definir a devolução dos logs ao fim do contrato. | L9: PE-09
A10: TS-04 | B10: Escopo SOC | C10: Integração do SIEM com 'todos os ativos relevantes' / volumetria | D10: Anexo I 1.4 | E10: Q&A #3; PPTX slide 2 | F10: SIEM integrado a todos os ativos relevantes. Q&A #3: a volumetria (EPS) será informada somente ao vencedor. PPTX: 850 servidores (70% Windows, 30% Linux), 2 data centers (SP e Campinas) e 2 nuvens públicas. | G10: Escopo aberto; EPS desconhecido | H10: Ambiguidade crítica (escopo e volumetria) | I10: Alto | J10: Licenças de SIEM e armazenamento costumam ser cobrados por EPS ou GB/dia. Sem a volumetria, o preço fixo carrega um risco ilimitado de sobrecusto. 'Ativos relevantes' não está definido: não se sabe se inclui estações, rede, aplicações, SaaS ou subsidiárias. | K10: Declarar uma premissa de EPS e GB/dia estimados (ex.: com base em 850 servidores, 2 DCs e 2 nuvens), com faixa contratada e preço unitário por excedente. Definir a lista de fontes de log no anexo da proposta. Insistir na volumetria via Q&A. | L10: PE-10
A11: TS-05 | B11: Escopo SOC | C11: Resposta a incidentes | D11: Anexo I 1.5 | E11: Anexo I 6.1 | F11: Resposta a incidentes, incluindo contenção, erradicação e relatório pós-incidente. | G11: IR incluso | H11: Ambiguidade (limites do IR) | I11: Alto | J11: Não há limites: não se sabe se o atendimento é remoto ou presencial, se inclui forense e recuperação, nem quantas horas ou incidentes estão cobertos. Somado à responsabilidade ilimitada (CT-05), executar contenção e erradicação aumenta a exposição. | K11: Definir o escopo de IR (remoto, banco de horas, forense como opcional) e as responsabilidades de cada parte em matriz RACI. | L11: PE-11
A12: TS-06 | B12: Escopo SOC | C12: Migração de 24 meses de logs históricos | D12: PPTX slide 5 | E12: Anexo I 1.3/1.6; PPTX slide 3 | F12: Expectativa apresentada no workshop: migrar 24 meses de logs históricos do SIEM legado para a nova plataforma. | G12: Fora do RFP/Anexo I: tratar como opcional | H12: ESCOPO NÃO FORMALIZADO | I12: Alto | J12: Não consta no RFP nem no Anexo I. O volume é desconhecido e a migração depende do fornecedor e do formato do SIEM legado, cujo contrato acaba em 31/01/2027. Se virar obrigação depois, gera custo não precificado. | K12: Perguntar via Q&A se faz parte do escopo. Cotar como item opcional e separado, com premissas de volume e formato e com a cooperação do fornecedor atual. | L12: PE-02
A13: SL-01 | B13: SLA | C13: Início de tratamento de incidentes críticos | D13: Anexo I 2.1 | E13: RFP 7.4 | F13: Tempo máximo de 15 minutos para iniciar o tratamento de incidentes críticos. | G13: 15 min | H13: — | I13: Alto | J13: Cada violação gera multa de 10% do valor mensal (CT-04). Não está definido o marco inicial: detecção, alerta ou abertura do chamado. | K13: Definir o marco de início e de 'início do tratamento'. Dimensionar o N2 de plantão. | L13: PE-12
A14: SL-04 | B14: SLA | C14: Classificação de criticidade | D14: Anexo I 2.4 | F14: A criticidade dos incidentes segue a matriz de classificação do Contratante. | G14: Matriz não fornecida | H14: Ambiguidade (matriz desconhecida) | I14: Alto | J14: O Contratante define sozinho o que é 'crítico' e, com isso, o volume de SLA de 15 minutos e de multas. | K14: Pedir a matriz. Propor que a classificação seja acordada na transição e que mudanças passem por governança. | L14: PE-12
A15: IA-01 | B15: Escopo IAM | C15: Ciclo de vida de identidades / revogação em 24h | D15: Anexo I 3.1 | E15: PPTX slide 3 | F15: Gestão de admissão, movimentação e desligamento, com revogação dos acessos de desligados em até 24 horas. Ambiente atual: Active Directory + scripts internos. | G15: Revogação em 24h | H15: Ambiguidade (gatilho e ferramenta) | I15: Alto | J15: O prazo depende de o RH comunicar o desligamento. Não se sabe se o proponente fornece ferramenta de IGA nem quais sistemas-alvo entram, além do AD. | K15: Definir o gatilho (evento do RH), os sistemas-alvo e se haverá ferramenta de IGA fornecida. Cotar a integração com o RH. | L15: PE-11
A16: DM-01 | B16: Dimensionamento | C16: Número de usuários | D16: Q&A #5 | E16: RFP 2.1; PPTX slide 2; PPTX notas slide 5 | F16: RFP 2.1: cerca de 4.500 colaboradores. PPTX: 6.200 usuários ativos. Notas do PPTX: mais cerca de 900 usuários das subsidiárias. Q&A #5: 'considerar 5.000 usuários'. | G16: 5.000 usuários (Q&A #5) com preço por excedente | H16: CONFLITO entre 4 números (4.500 / 5.000 / 6.200 / ~7.100) | I16: Alto | J16: O Q&A é a fonte oficial mais recente, mas o próprio banco mostrou 6.200 usuários ativos (talvez incluindo terceiros ou contas de serviço) e, com as subsidiárias, cerca de 7.100. Precificar só com 5.000 pode subdimensionar o serviço em até 42%. | K16: Precificar a base de 5.000 conforme o Q&A, com preço unitário por usuário adicional e faixas. Declarar a premissa na proposta e pedir a definição de 'usuário' (colaborador, terceiro, conta de serviço). | L16: PE-01
A17: DM-02 | B17: Dimensionamento | C17: Subsidiárias no escopo | D17: PPTX notas do slide 5 | E17: RFP 2.1 | F17: Nota do apresentador: Horizonte Seguros e Horizonte Investimentos (cerca de 900 usuários) também deverão entrar no escopo. | G17: Fora do RFP: tratar como opcional | H17: ESCOPO NÃO FORMALIZADO | I17: Alto | J17: Essa informação está só nas notas do apresentador. O RFP fala em contratante único. As subsidiárias são pessoas jurídicas distintas e podem ter outros reguladores (seguradora/SUSEP, gestora/CVM). Isso afeta partes do contrato, faturamento, Anexo III, SLA e responsabilidade. | K17: Perguntar via Q&A. Se confirmado, cotar como módulo opcional e exigir que as subsidiárias sejam partes ou intervenientes no contrato. | L17: PE-01
A18: CT-04 | B18: Contratual | C18: Multa por descumprimento de SLA | D18: RFP 7.4 | E18: Q&A #4; Anexo I 2 | F18: Multa de 10% do valor mensal do contrato por ocorrência de descumprimento de qualquer SLA. Q&A #4: 'as condições do item 7 permanecem inalteradas' (sem teto). | G18: 10% por ocorrência, SEM TETO | H18: Risco crítico (Q&A recusou limitar) | I18: Alto | J18: Dez ocorrências no mês consomem 100% da mensalidade. A multa vale para todos os SLAs, inclusive atraso de relatório, e a criticidade é definida pelo banco (SL-04). Não há gradação nem cura, e o tema não foi negociado no Q&A. | K18: Jurídico: propor teto mensal (ex.: 10-20% da fatura), gradação por SLA, período de carência na transição e exclusões. Pricing: provisionar risco. Avaliar se a proposta pode trazer ressalvas sem desclassificação. | L18: PE-16
A19: CT-05 | B19: Contratual | C19: Responsabilidade ilimitada | D19: RFP 7.5 | F19: A Contratada responde de forma integral e ilimitada por quaisquer danos decorrentes de incidentes de segurança no ambiente do Contratante. | G19: Ilimitada, sem nexo causal | H19: Risco crítico / possível no-go | I19: Alto | J19: Na redação atual, a Contratada responde por qualquer incidente no ambiente do banco, mesmo sem culpa ou nexo com o serviço (ex.: falha de sistema do próprio banco). Inclui danos indiretos e lucros cessantes. Nenhum seguro cobre esse risco, e a cláusula conflita com 7.6. | K19: Ponto de go/no-go. Propor responsabilidade limitada a 12 meses de contrato, apenas por culpa comprovada e excluindo danos indiretos. Escalar à diretoria. | L19: PE-16
A20: CT-07 | B20: Contratual | C20: Vedação à subcontratação | D20: RFP 7.7 | E20: Anexo I 1.2 | F20: É vedada a subcontratação, total ou parcial, do objeto. | G20: Vedada | H20: CONFLITO prático com SIEM em nuvem / fabricantes | I20: Alto | J20: O próprio Anexo I prevê SIEM em nuvem pública, ou seja, um hyperscaler. Suporte de fabricante, threat intel de terceiros e forense especializada também podem ser vistos como subcontratação. A vedação também impede consórcio ou parceiro para IAM. | K20: Pedir confirmação de que provedores de nuvem, licenças e suporte de fabricantes não são subcontratação. Listar os terceiros na proposta. | L20: PE-17
A21: CT-09 | B21: Contratual | C21: Hierarquia entre documentos | D21: RFP (omissão) | E21: Q&A; Anexo I; PPTX | F21: O RFP não define a precedência entre RFP, anexos, Q&A e materiais do workshop. | G21: Adotada: Q&A > RFP > Anexo I > questionário > workshop | H21: LACUNA | I21: Alto | J21: Há pelo menos 5 conflitos entre os documentos (CR-05, TS-02, TS-03, DM-01, AV-02). Sem regra de precedência, o banco pode exigir a interpretação mais onerosa. | K21: Pedir cláusula de precedência. Na proposta, declarar a interpretação adotada para cada conflito. | L21: PE-01
A22: RG-01 | B22: Regulatório | C22: Resolução CMN nº 4.893/2021 | D22: RFP 1.2 | E22: QT-04 (obrigatório, peso 3); Anexo III; Anexo I 1.2 | F22: O banco está sujeito à Res. CMN 4.893/2021 (política de segurança cibernética e contratação de processamento, armazenamento e nuvem). | G22: Conformidade exigida | H22: Relacionado ao conflito TS-02 | I22: Alto | J22: A norma impõe requisitos contratuais à contratação de serviços relevantes de processamento e nuvem (acesso do BCB, continuidade, comunicação ao regulador etc.). QT-04 é obrigatório e tem o maior peso. Confirmar a redação vigente da norma, que pode ter sido alterada. | K22: Montar um anexo de conformidade com a Res. 4.893 (cláusulas exigidas, acesso do BCB, plano de continuidade, localização no Brasil) e conferir a versão vigente. | L22: PE-06
A23: CR-06 | B23: Cronograma | C23: Operação paralela sem custo | D23: Anexo I 4.2 | E23: PPTX slide 3 | F23: Durante a transição, operar em paralelo com o fornecedor atual, sem custo adicional para o Contratante. | G23: Paralelo sem custo adicional | H23: Ambiguidade (duração do paralelo) | I23: Médio | J23: O custo da operação paralela tem de ser diluído na mensalidade. A duração depende de CR-05 e fica limitada pelo fim do SIEM legado em 31/01/2027. | K23: Embutir o custo de transição e paralelo no preço, ou em uma linha de setup se o Anexo IV permitir. Limitar o paralelo ao prazo de transição. | L23: PE-04
A24: CR-07 | B24: Cronograma | C24: Documentação do ambiente pelo Contratante | D24: Anexo I 6.2 | E24: Anexo I 6.1 | F24: Contratante entrega a documentação técnica em até 10 dias após a assinatura e disponibiliza VPN (6.1). | G24: 10 dias após a assinatura | H24: Ambiguidade (impacto no prazo de 30 dias) | I24: Médio | J24: Com transição de 30 dias, o banco pode consumir até 1/3 do prazo antes de entregar a documentação. Não há previsão de que atrasos do Contratante suspendam os prazos da Contratada. | K24: Incluir premissa: prazos de transição e SLAs ficam suspensos enquanto houver pendências do Contratante (documentação, VPN, acessos). | L24: PE-04
A25: PR-04 | B25: Proposta (forma) | C25: Anexo II | D25: RFP (numeração) | F25: O RFP menciona Anexos I, III e IV. O Anexo II não é citado nem foi recebido. | G25: Anexo II desconhecido | H25: DOCUMENTO AUSENTE / lacuna | I25: Médio | J25: Pode ser a minuta de contrato ou um modelo de atestado. Se for a minuta, é essencial para o jurídico. | K25: Confirmar no portal se existe Anexo II (minuta contratual?) e pedir o envio. | L25: PE-05
A26: TS-07 | B26: Escopo SOC | C26: Meta de falsos positivos | D26: PPTX slide 4 | E26: Anexo I 2 | F26: Hoje são cerca de 1.200 alertas/dia e 70% de falsos positivos. Meta: 10% de falsos positivos no primeiro trimestre de operação. | G26: Não é SLA contratual (não consta no Anexo I 2) | H26: Expectativa x SLA | I26: Médio | J26: Sair de 70% para 10% em 3 meses é agressivo, depende do tuning e da cooperação do banco e pode virar critério de aceite informal. Se for incluída como SLA, incide multa de 10% (CT-04). | K26: Apresentar a redução de falsos positivos como plano de tuning progressivo, sem compromisso contratual de 10% no primeiro trimestre. Pedir confirmação de que não é SLA. | L26: PE-02
A27: TS-10 | B27: Escopo SOC | C27: Threat intelligence | D27: QT-05 (não obrigatório, peso 2) | E27: Aba Pesos | F27: Serviço de threat intelligence. | G27: Oferecer: 'Não atende' = -2 pts | H27: Ver AV-05 | I27: Médio | J27: Não consta no Anexo I. Feeds de threat intel podem processar dados fora do Brasil, o que conflita com o Anexo III. | K27: Incluir threat intel (feeds e boletins) com garantia de que os dados do banco não saem do país. | L27: PE-08
A28: SL-02 | B28: SLA | C28: Disponibilidade do SIEM | D28: Anexo I 2.2 | E28: RFP 7.4 | F28: Disponibilidade mínima mensal de 99,9% da plataforma SIEM. | G28: 99,9% mensal (~43 min/mês) | H28: — | I28: Médio | J28: Depende do SLA do provedor de nuvem e do fabricante. Não define janelas de manutenção nem exclusões. | K28: Prever exclusões (manutenção programada, força maior, falhas do Contratante) e alinhar com o SLA do hyperscaler. | L28: PE-12
A29: EQ-01 | B29: Equipe | C29: Coordenador CISSP dedicado | D29: Anexo I 5.1 | E29: RFP 5.2 | F29: Coordenador com certificação CISSP, dedicado exclusivamente ao contrato. | G29: 1 FTE CISSP exclusivo | H29: — | I29: Médio | J29: Custo fixo relevante. Exigirá substituição equivalente em férias ou desligamento. | K29: Precificar 1 FTE sênior exclusivo e definir regra de substituto. | L29: —
A30: CT-03 | B30: Contratual | C30: Prazo de pagamento | D30: RFP 7.3 | F30: Pagamento em até 60 dias após o aceite da nota fiscal. | G30: 60 dias após aceite | H30: Ambiguidade (critério de aceite) | I30: Médio | J30: Prazo longo, com custo financeiro. O prazo e o critério do aceite não estão definidos, então o ciclo real pode passar de 90 dias. | K30: Incluir o custo financeiro no preço. Propor aceite tácito em X dias. | L30: PE-16
A31: CT-06 | B31: Contratual | C31: Seguro cyber | D31: RFP 7.6 | E31: RFP 7.5 | F31: Manter seguro de responsabilidade civil cibernética 'em valor compatível com os riscos do contrato'. | G31: Valor indefinido | H31: Ambiguidade | I31: Médio | J31: 'Compatível' é subjetivo e, junto com 7.5 (ilimitado), não tem referência. | K31: Pedir o valor mínimo da apólice. Cotar o prêmio com a corretora. | L31: PE-16
A32: CT-10 | B32: Contratual | C32: Minuta de contrato / LGPD | D32: RFP (omissão) | F32: Não foi recebida minuta de contrato, nem cláusula de proteção de dados pessoais (LGPD, papel de operador), de propriedade dos logs ou de devolução de dados no fim do contrato. | G32: Não tratado | H32: LACUNA | I32: Médio | J32: O SOC e o IAM tratam dados pessoais de colaboradores. Faltam regras de devolução e eliminação dos logs no fim do contrato, o que se liga à retenção de 5 anos. | K32: Pedir a minuta contratual (talvez seja o Anexo II) e as cláusulas de proteção de dados. | L32: PE-05
A33: SL-03 | B33: SLA | C33: Relatório mensal | D33: Anexo I 2.3 | E33: RFP 7.4 | F33: Relatório mensal de indicadores até o 5º dia útil do mês seguinte. | G33: 5º dia útil | H33: — | I33: Baixo | J33: Um atraso, mesmo pequeno, gera multa de 10% (CT-04), uma penalidade desproporcional. | K33: Automatizar o relatório. Pedir multas graduadas por tipo de SLA. | L33: PE-12
A34: CT-01 | B34: Contratual | C34: Vigência | D34: RFP 7.1 | F34: 36 meses, prorrogável por iguais períodos mediante acordo. | G34: 36 meses | H34: — | I34: Baixo | J34: Base para amortizar setup e transição. | K34: Amortizar setup em 36 meses e prever multa rescisória por término antecipado. | L34: —
A35: CT-08 | B35: Contratual | C35: Confidencialidade | D35: RFP 7.8 | F35: Confidencialidade por 5 anos após o término do contrato. | G35: 5 anos pós-término | H35: — | I35: Baixo | J35: Prazo usual. | K35: Verificar compatibilidade com a retenção de logs de 5 anos (TS-03). | L35: —

Sheet Pricing
A1: ID | B1: Categoria | C1: Tema | D1: Fonte principal | E1: Outras fontes | F1: Requisito / conteúdo (resumo) | G1: Posição vigente (após Q&A) | H1: Conflito / ambiguidade | I1: Risco | J1: Análise | K1: Ação recomendada | L1: Pergunta (ref.)
A2: CR-04 | B2: Cronograma | C2: Início dos serviços x fim do SIEM legado | D2: RFP 3.1 | E2: PPTX slide 3 | F2: Início previsto em 01/02/2027. O contrato do SIEM legado termina em 31/01/2027, sem possibilidade de prorrogação. | G2: 01/02/2027 (go-live sem folga) | H2: Sem margem de contingência | I2: Alto | J2: Não há folga: se o novo SIEM não estiver operando em 01/02/2027, o banco fica sem monitoramento. A migração de 24 meses de logs (TS-06) também precisa acontecer antes de 31/01/2027, enquanto o legado ainda existe. A data de assinatura do contrato não foi informada. | K2: Pedir a data prevista de assinatura. Condicionar os prazos de transição à assinatura e ao cumprimento das obrigações do Contratante. Prever plano de contingência. | L2: PE-03
A3: CR-05 | B3: Cronograma | C3: Prazo de transição | D3: RFP 3.2 | E3: Anexo I 4.1 | F3: RFP 3.2: transição concluída em até 30 dias corridos da assinatura. Anexo I 4.1: até 60 dias corridos da assinatura. | G3: INDEFINIDO: 30 x 60 dias (adotar 30 dias como pior caso) | H3: CONFLITO RFP x Anexo I | I3: Alto | J3: Os dois documentos divergem e o Q&A não tratou do tema. O plano de transição vale 10 pontos (6.2). Com 30 dias, a equipe de onboarding fica mais concentrada e mais cara. Somado à multa de 10% por SLA (CT-04), o atraso na transição é um risco relevante. | K3: Pedir esclarecimento. Precificar e planejar para 30 dias, com a premissa de que a contagem só corre após a entrega da documentação (CR-07) e dos acessos (VPN). | L3: PE-04
A4: PR-03 | B4: Proposta (forma) | C4: Planilha de preços (Anexo IV) | D4: RFP 4.3 | F4: Proposta comercial conforme a planilha modelo do Anexo IV — Planilha de Preços. | G4: Anexo IV NÃO RECEBIDO | H4: DOCUMENTO AUSENTE | I4: Alto | J4: O Anexo IV não está entre os arquivos recebidos. Sem ele não se sabe a estrutura de preço (por usuário, por EPS, fixo mensal, setup), o que impede o pricing final. | K4: Baixar o Anexo IV no portal. Se não existir, pedir via Q&A. | L4: PE-05
A5: PR-06 | B5: Proposta (forma) | C5: Declaração de localização de dados (Anexo III) | D5: RFP p.6 (Anexo III, escaneado) | E5: RFP 5.1c; Q&A #2 | F5: Declaração assinada pelo representante legal: todos os dados do Banco, inclusive logs de segurança, serão armazenados e processados exclusivamente em território nacional durante toda a vigência. Deve ser entregue com a proposta, sob pena de inabilitação. | G5: Obrigatória: dados e logs só no Brasil | H5: CONFLITO com Anexo I 1.2 (nuvem em região livre) | I5: Alto | J5: A declaração vincula toda a cadeia: SIEM em nuvem, backups, DR, threat intel e suporte do fabricante com acesso a dados. Assinar exige garantir que nenhum componente (inclusive telemetria do fabricante do SIEM) processe dados fora do Brasil. A página é imagem, sem texto extraível. | K5: Validar a arquitetura antes da assinatura: região Brasil do hyperscaler, DR no Brasil e suporte do fabricante sem acesso a dados fora do país. Colher a assinatura do representante legal com procuração válida. | L5: PE-06
A6: HB-03 | B6: Habilitação | C6: SOC em território nacional | D6: RFP 5.1c | E6: Q&A #2; Anexo III | F6: Comprovar que o SOC está localizado em território nacional. Q&A #2: não é permitido operar o SOC a partir de outro país. | G6: SOC no Brasil (confirmado no Q&A #2) | H6: Confirmado pelo Q&A | I6: Alto | J6: Exclui follow-the-sun com centros no exterior. O RFP não define o meio de comprovação. | K6: Preparar a comprovação (endereço, contrato de locação, fotos, certificação do site). | L6: —
